Этот код определяет новый класс исключений под названием DivideByZeroException, который является производным от класса std::exception. 
В этом коде не определен конструктор, поэтому он наследует конструктор по умолчанию класса std::exception.

Метод what() переопределяется в этом пользовательском классе исключений, чтобы вернуть пользовательское сообщение об ошибке, хранящееся в строковой переменной error_message. 
Метод помечен const throw(), чтобы указать, что он сам не будет вызывать исключений, а также для обеспечения совместимости с производными классами, что означает, что метод не будет изменять никакие члены класса и не позволит никаким исключениям распространяться из функции.

Этот пользовательский класс исключений можно использовать в блоке try-catch для обработки ошибок деления на ноль или других специфических ошибок, которые могут возникнуть во время выполнения. 
Когда выбрасывается объект DivideByZeroException, блок catch может получить доступ к пользовательскому сообщению об ошибке и предпринять соответствующие действия, например, вывести сообщение об ошибке пользователю.

